<?xml version="1.0" ?>
<!-- =================================================================================== -->
<!-- |    This document was autogenerated by xacro from human_torso.xacro              | -->
<!-- |    EDITING THIS FILE BY HAND IS NOT RECOMMENDED                                 | -->
<!-- =================================================================================== -->
<!--
Parameters:
- offsets
    - neck to shoulder
    - shoulder to elbow
    - elbow to wrist

- joint limits (source: https://design.tutsplus.com/articles/human-anatomy-fundamentals-flexibility-and-joint-limitations-vector-25401)
    - shoulder
        - abduction 180
        - adduction -45
        - horizontal flexion 130
        - horizontal extension -45
        - vertical flexion 180
        - vertical extension -60
    - elbow
        - flexion -150
        - extension 0
        - supination 180
        - pronation -90

    - wrist
        - extension 70
        - flexion 90
        - radial 20
        - ulnar 50

-->
<robot name="human_torso" xmlns:xacro="http://www.ros.org/wiki/xacro">
  <material name="white">
    <color rgba="1.0 1.0 1.0 1.0"/>
  </material>
  <link name="base_link">
    <inertial>
      <mass value="0.01"/>
      <origin rpy="0 0 0" xyz="0 0 0"/>
      <inertia ixx="0.001" ixy="0" ixz="0" iyy="0.001" iyz="0" izz="0.001"/>
    </inertial>
  </link>
  <link name="torso_pan">
    <inertial>
      <mass value="0.01"/>
      <origin rpy="0 0 0" xyz="0 0 0"/>
      <inertia ixx="0.001" ixy="0" ixz="0" iyy="0.001" iyz="0" izz="0.001"/>
    </inertial>
  </link>
  <link name="torso">
    <visual>
      <geometry>
        <mesh filename=".//torso.obj"/>
      </geometry>
      <origin rpy="0 0 0" xyz="0 0 0"/>
      <material name="white"/>
    </visual>
    <collision>
      <geometry>
        <box size="0.2 0.22 0.59"/>
      </geometry>
      <origin rpy="0 0 0" xyz="0 0 0.295"/>
    </collision>
    <inertial>
      <mass value="40.0"/>
      <origin rpy="0 0 0" xyz="0 0 0"/>
      <inertia ixx="4.0" ixy="0" ixz="0" iyy="4.0" iyz="0" izz="4.0"/>
    </inertial>
  </link>
  <joint name="torso_pan_joint" type="revolute">
    <axis xyz="0 0 1"/>
    <limit effort="10000.0" lower="-1.22173" upper="1.22173" velocity="1.57"/>
    <origin rpy="0 0 0" xyz="0 0 0"/>
    <parent link="base_link"/>
    <child link="torso_pan"/>
  </joint>
  <joint name="torso_tilt_joint" type="revolute">
    <axis xyz="0 1 0"/>
    <limit effort="10000.0" lower="-0.32173" upper="0.32173" velocity="1.57"/>
    <origin rpy="0 0 0" xyz="0 0 0"/>
    <parent link="torso_pan"/>
    <child link="torso"/>
  </joint>
  <link name="l_shoulder_abduction_adduction">
    <inertial>
      <mass value="0.01"/>
      <origin rpy="0 0 0" xyz="0 0 0"/>
      <inertia ixx="0.001" ixy="0" ixz="0" iyy="0.001" iyz="0" izz="0.001"/>
    </inertial>
  </link>
  <link name="l_shoulder_horizontal_flexion_extension">
    <inertial>
      <mass value="0.01"/>
      <origin rpy="0 0 0" xyz="0 0 0"/>
      <inertia ixx="0.001" ixy="0" ixz="0" iyy="0.001" iyz="0" izz="0.001"/>
    </inertial>
  </link>
  <link name="l_shoulder_vertical_flexion_extension">
    <visual>
      <geometry>
        <mesh filename=".//l_arm.obj"/>
      </geometry>
      <origin rpy="0 0 0" xyz="0 0 0"/>
      <material name="white"/>
    </visual>
    <collision>
      <geometry>
        <box size="0.1 0.07 0.33"/>
      </geometry>
      <origin rpy="0.1 0 0" xyz="0 0.015 -0.135"/>
    </collision>
    <inertial>
      <mass value="3.5"/>
      <origin rpy="0 0 0" xyz="0 0 0"/>
      <inertia ixx="0.3" ixy="0" ixz="0" iyy="0.3" iyz="0" izz="0.3"/>
    </inertial>
  </link>
  <link name="l_elbow_flexion_extension">
    <inertial>
      <mass value="0.01"/>
      <origin rpy="0 0 0" xyz="0 0 0"/>
      <inertia ixx="0.001" ixy="0" ixz="0" iyy="0.001" iyz="0" izz="0.001"/>
    </inertial>
  </link>
  <link name="l_elbow_pronation_supination">
    <visual>
      <geometry>
        <mesh filename=".//l_forearm.obj"/>
      </geometry>
      <origin rpy="0 0 0" xyz="0 0 0"/>
      <material name="white"/>
    </visual>
    <collision>
      <geometry>
        <box size="0.07 0.07 0.2"/>
      </geometry>
      <origin rpy="0.2 -0.2 0" xyz="0.02 0.015 -0.1"/>
    </collision>
    <inertial>
      <mass value="2.5"/>
      <origin rpy="0 0 0" xyz="0 0 0"/>
      <inertia ixx="0.2" ixy="0" ixz="0" iyy="0.2" iyz="0" izz="0.2"/>
    </inertial>
  </link>
  <link name="l_wrist_flexion_extension">
    <inertial>
      <mass value="0.01"/>
      <origin rpy="0 0 0" xyz="0 0 0"/>
      <inertia ixx="0.001" ixy="0" ixz="0" iyy="0.001" iyz="0" izz="0.001"/>
    </inertial>
  </link>
  <link name="l_wrist_radial_ulnar">
    <visual>
      <geometry>
        <mesh filename=".//l_hand.obj"/>
      </geometry>
      <origin rpy="0 0 0" xyz="0 0 0"/>
      <material name="white"/>
    </visual>
    <collision>
      <geometry>
        <mesh filename=".//l_hand.obj"/>
        <!--<box size="${palm_width} ${palm_depth} ${palm_height}"/>-->
      </geometry>
      <!--origin xyz="0.025 ${reflect*0.0} ${-palm_height/2 + 0.02}" rpy="0 0 0"/-->
      <origin rpy="0 0 0" xyz="0 0 0"/>
    </collision>
    <inertial>
      <mass value="1.5"/>
      <origin rpy="0 0 0" xyz="0 0 0"/>
      <inertia ixx="0.1" ixy="0" ixz="0" iyy="0.1" iyz="0" izz="0.1"/>
    </inertial>
  </link>
  <joint name="l_shoulder_abduction_adduction_joint" type="revolute">
    <axis xyz="1 0 0"/>
    <limit effort="1000.0" lower="0.1" upper="3.1415" velocity="2.5"/>
    <origin rpy="0 0 0" xyz=" 0 0.10988 0.4938"/>
    <parent link="torso"/>
    <child link="l_shoulder_abduction_adduction"/>
  </joint>
  <joint name="l_shoulder_horizontal_flexion_extension_joint" type="revolute">
    <axis xyz="0 0 -1"/>
    <limit effort="1000.0" lower="-0.78539" upper="2.26892" velocity="2.5"/>
    <origin rpy="0 0 0" xyz="0 0 0"/>
    <parent link="l_shoulder_abduction_adduction"/>
    <child link="l_shoulder_horizontal_flexion_extension"/>
  </joint>
  <joint name="l_shoulder_vertical_flexion_extension_joint" type="revolute">
    <axis xyz="0 -1 0"/>
    <limit effort="1000.0" lower="-1.04719" upper="3.1415" velocity="2.5"/>
    <origin rpy="0 0 0" xyz="0 0 0"/>
    <parent link="l_shoulder_horizontal_flexion_extension"/>
    <child link="l_shoulder_vertical_flexion_extension"/>
  </joint>
  <joint name="l_elbow_flexion_extension_joint" type="revolute">
    <axis xyz="0 1 0"/>
    <limit effort="1000.0" lower="-2.61799" upper="0" velocity="2.5"/>
    <origin rpy="0 0 0" xyz="-0.01223 0.03506 -0.283379"/>
    <parent link="l_shoulder_vertical_flexion_extension"/>
    <child link="l_elbow_flexion_extension"/>
  </joint>
  <joint name="l_elbow_pronation_supination_joint" type="revolute">
    <axis xyz="0 0 -1"/>
    <limit effort="1000.0" lower="-3.1415" upper="1.57079" velocity="2.5"/>
    <origin rpy="0 0 0" xyz="0 0 0"/>
    <parent link="l_elbow_flexion_extension"/>
    <child link="l_elbow_pronation_supination"/>
  </joint>
  <joint name="l_wrist_flexion_extension_joint" type="revolute">
    <axis xyz="0 -1 0"/>
    <limit effort="1000.0" lower="-1.57079" upper="1.22173" velocity="2.5"/>
    <origin rpy="0 0 0" xyz="0.03606 0.02363 -0.19094"/>
    <parent link="l_elbow_pronation_supination"/>
    <child link="l_wrist_flexion_extension"/>
  </joint>
  <joint name="l_wrist_radial_ulnar_joint" type="revolute">
    <axis xyz="1 0 0"/>
    <limit effort="1000.0" lower="-0.34906" upper="0.87266" velocity="2.5"/>
    <origin rpy="0 0 0" xyz="0 0 0"/>
    <parent link="l_wrist_flexion_extension"/>
    <child link="l_wrist_radial_ulnar"/>
  </joint>
  <link name="l_tip">
    <visual>
      <geometry>
        <box size="0.001 0.01 0.001"/>
      </geometry>
      <origin rpy="0 0 0" xyz="0 0 0"/>
      <material name="white"/>
    </visual>
    <collision>
      <geometry>
        <box size="0.001 0.01 0.001"/>
      </geometry>
      <origin rpy="0 0 0" xyz="0 0 0"/>
    </collision>
    <inertial>
      <mass value="0.001"/>
      <origin rpy="0 0 0" xyz="0 0 0"/>
      <inertia ixx="0.0001" ixy="0" ixz="0" iyy="0.0001" iyz="0" izz="0.0001"/>
    </inertial>
  </link>
  <joint name="l_tip_joint" type="fixed">
    <origin rpy="0 3.1415 0" xyz="0.03 0.015 -0.23"/>
    <parent link="l_wrist_radial_ulnar"/>
    <child link="l_tip"/>
  </joint>
  <link name="r_shoulder_abduction_adduction">
    <inertial>
      <mass value="0.01"/>
      <origin rpy="0 0 0" xyz="0 0 0"/>
      <inertia ixx="0.001" ixy="0" ixz="0" iyy="0.001" iyz="0" izz="0.001"/>
    </inertial>
  </link>
  <link name="r_shoulder_horizontal_flexion_extension">
    <inertial>
      <mass value="0.01"/>
      <origin rpy="0 0 0" xyz="0 0 0"/>
      <inertia ixx="0.001" ixy="0" ixz="0" iyy="0.001" iyz="0" izz="0.001"/>
    </inertial>
  </link>
  <link name="r_shoulder_vertical_flexion_extension">
    <visual>
      <geometry>
        <mesh filename=".//r_arm.obj"/>
      </geometry>
      <origin rpy="0 0 0" xyz="0 0 0"/>
      <material name="white"/>
    </visual>
    <collision>
      <geometry>
        <box size="0.1 0.07 0.33"/>
      </geometry>
      <origin rpy="-0.1 0 0" xyz="0 -0.015 -0.135"/>
    </collision>
    <inertial>
      <mass value="3.5"/>
      <origin rpy="0 0 0" xyz="0 0 0"/>
      <inertia ixx="0.3" ixy="0" ixz="0" iyy="0.3" iyz="0" izz="0.3"/>
    </inertial>
  </link>
  <link name="r_elbow_flexion_extension">
    <inertial>
      <mass value="0.01"/>
      <origin rpy="0 0 0" xyz="0 0 0"/>
      <inertia ixx="0.001" ixy="0" ixz="0" iyy="0.001" iyz="0" izz="0.001"/>
    </inertial>
  </link>
  <link name="r_elbow_pronation_supination">
    <visual>
      <geometry>
        <mesh filename=".//r_forearm.obj"/>
      </geometry>
      <origin rpy="0 0 0" xyz="0 0 0"/>
      <material name="white"/>
    </visual>
    <collision>
      <geometry>
        <box size="0.07 0.07 0.2"/>
      </geometry>
      <origin rpy="-0.2 -0.2 0" xyz="0.02 -0.015 -0.1"/>
    </collision>
    <inertial>
      <mass value="2.5"/>
      <origin rpy="0 0 0" xyz="0 0 0"/>
      <inertia ixx="0.2" ixy="0" ixz="0" iyy="0.2" iyz="0" izz="0.2"/>
    </inertial>
  </link>
  <link name="r_wrist_flexion_extension">
    <inertial>
      <mass value="0.01"/>
      <origin rpy="0 0 0" xyz="0 0 0"/>
      <inertia ixx="0.001" ixy="0" ixz="0" iyy="0.001" iyz="0" izz="0.001"/>
    </inertial>
  </link>
  <link name="r_wrist_radial_ulnar">
    <visual>
      <geometry>
        <mesh filename=".//r_hand.obj"/>
      </geometry>
      <origin rpy="0 0 0" xyz="0 0 0"/>
      <material name="white"/>
    </visual>
    <collision>
      <geometry>
        <mesh filename=".//r_hand.obj"/>
        <!--<box size="${palm_width} ${palm_depth} ${palm_height}"/>-->
      </geometry>
      <!--origin xyz="0.025 ${reflect*0.0} ${-palm_height/2 + 0.02}" rpy="0 0 0"/-->
      <origin rpy="0 0 0" xyz="0 0 0"/>
    </collision>
    <inertial>
      <mass value="1.5"/>
      <origin rpy="0 0 0" xyz="0 0 0"/>
      <inertia ixx="0.1" ixy="0" ixz="0" iyy="0.1" iyz="0" izz="0.1"/>
    </inertial>
  </link>
  <joint name="r_shoulder_abduction_adduction_joint" type="fixed">
    <axis xyz="-1 0 0"/>
    <limit effort="1000.0" lower="0.1" upper="3.1415" velocity="2.5"/>
    <origin rpy="0 0 0" xyz=" -0.00304 -0.10786 0.49489"/>
    <parent link="torso"/>
    <child link="r_shoulder_abduction_adduction"/>
  </joint>
  <joint name="r_shoulder_horizontal_flexion_extension_joint" type="fixed">
    <axis xyz="0 0 1"/>
    <limit effort="1000.0" lower="-0.78539" upper="2.26892" velocity="2.5"/>
    <origin rpy="0 0 0" xyz="0 0 0"/>
    <parent link="r_shoulder_abduction_adduction"/>
    <child link="r_shoulder_horizontal_flexion_extension"/>
  </joint>
  <joint name="r_shoulder_vertical_flexion_extension_joint" type="fixed">
    <axis xyz="0 -1 0"/>
    <limit effort="1000.0" lower="-1.04719" upper="3.1415" velocity="2.5"/>
    <origin rpy="0 0 0" xyz="0 0 0"/>
    <parent link="r_shoulder_horizontal_flexion_extension"/>
    <child link="r_shoulder_vertical_flexion_extension"/>
  </joint>
  <joint name="r_elbow_flexion_extension_joint" type="fixed">
    <axis xyz="0 1 0"/>
    <limit effort="1000.0" lower="-2.61799" upper="0" velocity="2.5"/>
    <origin rpy="0 0 0" xyz="-0.01223 -0.03506 -0.283379"/>
    <parent link="r_shoulder_vertical_flexion_extension"/>
    <child link="r_elbow_flexion_extension"/>
  </joint>
  <joint name="r_elbow_pronation_supination_joint" type="fixed">
    <axis xyz="0 0 -1"/>
    <limit effort="1000.0" lower="-3.1415" upper="1.57079" velocity="2.5"/>
    <origin rpy="0 0 0" xyz="0 0 0"/>
    <parent link="r_elbow_flexion_extension"/>
    <child link="r_elbow_pronation_supination"/>
  </joint>
  <joint name="r_wrist_flexion_extension_joint" type="fixed">
    <axis xyz="0 -1 0"/>
    <limit effort="1000.0" lower="-1.57079" upper="1.22173" velocity="2.5"/>
    <origin rpy="0 0 0" xyz="0.03606 -0.02363 -0.19094"/>
    <parent link="r_elbow_pronation_supination"/>
    <child link="r_wrist_flexion_extension"/>
  </joint>
  <joint name="r_wrist_radial_ulnar_joint" type="fixed">
    <axis xyz="-1 0 0"/>
    <limit effort="1000.0" lower="-0.34906" upper="0.87266" velocity="2.5"/>
    <origin rpy="0 0 0" xyz="0 0 0"/>
    <parent link="r_wrist_flexion_extension"/>
    <child link="r_wrist_radial_ulnar"/>
  </joint>
  <link name="r_tip">
    <visual>
      <geometry>
        <box size="0.001 0.01 0.001"/>
      </geometry>
      <origin rpy="0 0 0" xyz="0 0 0"/>
      <material name="white"/>
    </visual>
    <collision>
      <geometry>
        <box size="0.001 0.01 0.001"/>
      </geometry>
      <origin rpy="0 0 0" xyz="0 0 0"/>
    </collision>
    <inertial>
      <mass value="0.001"/>
      <origin rpy="0 0 0" xyz="0 0 0"/>
      <inertia ixx="0.0001" ixy="0" ixz="0" iyy="0.0001" iyz="0" izz="0.0001"/>
    </inertial>
  </link>
  <joint name="r_tip_joint" type="fixed">
    <origin rpy="0 -3.1415 0" xyz="0.03 -0.015 -0.23"/>
    <parent link="r_wrist_radial_ulnar"/>
    <child link="r_tip"/>
  </joint>
  <link name="head_head_roll">
    <visual>
      <geometry>
        <mesh filename=".//head.obj"/>
      </geometry>
      <origin rpy="0 0 0" xyz="0 0 0"/>
      <material name="white"/>
    </visual>
    <collision>
      <geometry>
        <box size="0.32 0.27 0.4"/>
      </geometry>
      <origin rpy="0 0 0" xyz="0.03 0 0.18"/>
    </collision>
    <inertial>
      <mass value="5.0"/>
      <origin rpy="0 0 0" xyz="0 0 0"/>
      <inertia ixx="0.5" ixy="0" ixz="0" iyy="0.5" iyz="0" izz="0.5"/>
    </inertial>
  </link>
  <link name="head_head_tilt">
    <inertial>
      <mass value="0.01"/>
      <origin rpy="0 0 0" xyz="0 0 0"/>
      <inertia ixx="0.001" ixy="0" ixz="0" iyy="0.001" iyz="0" izz="0.001"/>
    </inertial>
  </link>
  <link name="head_head_pan">
    <inertial>
      <mass value="0.01"/>
      <origin rpy="0 0 0" xyz="0 0 0"/>
      <inertia ixx="0.001" ixy="0" ixz="0" iyy="0.001" iyz="0" izz="0.001"/>
    </inertial>
  </link>
  <joint name="head_pan_joint" type="fixed">
    <axis xyz="0 0 1"/>
    <limit effort="1000.0" lower="-1.22173" upper="1.22173" velocity="0.5"/>
    <origin rpy="0 0 0" xyz=" 0.0255 0 0.59"/>
    <parent link="torso"/>
    <child link="head_head_pan"/>
  </joint>
  <joint name="head_tilt_joint" type="fixed">
    <axis xyz="0 1 0"/>
    <limit effort="1000.0" lower="-1.57079" upper="0.95993" velocity="0.5"/>
    <origin rpy="0 0 0" xyz="0 0 0"/>
    <parent link="head_head_pan"/>
    <child link="head_head_tilt"/>
  </joint>
  <joint name="head_roll_joint" type="fixed">
    <axis xyz="1 0 0"/>
    <limit effort="1000.0" lower="-0.61086" upper="0.61086" velocity="0.5"/>
    <origin rpy="0 0 0" xyz="0 0 0"/>
    <parent link="head_head_tilt"/>
    <child link="head_head_roll"/>
  </joint>
</robot>
